Traceback (most recent call last):
  File "C:\Users\sofmo\miniconda3\envs\Mapa\lib\site-packages\jupyter_cache\executors\utils.py", line 58, in single_nb_execution
    executenb(
  File "C:\Users\sofmo\miniconda3\envs\Mapa\lib\site-packages\nbclient\client.py", line 1314, in execute
    return NotebookClient(nb=nb, resources=resources, km=km, **kwargs).execute()
  File "C:\Users\sofmo\miniconda3\envs\Mapa\lib\site-packages\jupyter_core\utils\__init__.py", line 165, in wrapped
    return loop.run_until_complete(inner)
  File "C:\Users\sofmo\miniconda3\envs\Mapa\lib\asyncio\base_events.py", line 647, in run_until_complete
    return future.result()
  File "C:\Users\sofmo\miniconda3\envs\Mapa\lib\site-packages\nbclient\client.py", line 709, in async_execute
    await self.async_execute_cell(
  File "C:\Users\sofmo\miniconda3\envs\Mapa\lib\site-packages\nbclient\client.py", line 1062, in async_execute_cell
    await self._check_raise_for_error(cell, cell_index, exec_reply)
  File "C:\Users\sofmo\miniconda3\envs\Mapa\lib\site-packages\nbclient\client.py", line 918, in _check_raise_for_error
    raise CellExecutionError.from_cell_and_msg(cell, exec_reply_content)
nbclient.exceptions.CellExecutionError: An error occurred while executing the following cell:
------------------
import pandas as pd
import geopandas as gpd
import matplotlib.pyplot as plt
import seaborn as sns

trimestre1 = pd.read_csv("precios.csv")
trimestre2 = pd.read_csv("precios (1).csv")
trimestre3 = pd.read_csv("precios (2).csv")
trimestre4 = pd.read_csv("precios (3).csv")

trimestre1.columns = trimestre1.columns.str.replace(' ', '')
trimestre2.columns = trimestre2.columns.str.replace(' ', '')
trimestre3.columns = trimestre3.columns.str.replace(' ', '')
trimestre4.columns = trimestre4.columns.str.replace(' ', '')

------------------


[1;31m------------------------------------------------------------------------[0m
[1;31mModuleNotFoundError[0m                    Traceback (most recent call last)
Cell [1;32mIn[1], line 1[0m
[1;32m----> 1[0m [38;5;28;01mimport[39;00m [38;5;21;01mpandas[39;00m [38;5;28;01mas[39;00m [38;5;21;01mpd[39;00m
[0;32m      2[0m [38;5;28;01mimport[39;00m [38;5;21;01mgeopandas[39;00m [38;5;28;01mas[39;00m [38;5;21;01mgpd[39;00m
[0;32m      3[0m [38;5;28;01mimport[39;00m [38;5;21;01mmatplotlib[39;00m[38;5;21;01m.[39;00m[38;5;21;01mpyplot[39;00m [38;5;28;01mas[39;00m [38;5;21;01mplt[39;00m

[1;31mModuleNotFoundError[0m: No module named 'pandas'

